Workbook

Sheet Bets
A1: Date | B1: Event | C1: Selection | D1: Type | E1: Target | F1: Fill | G1: Stake $ | H1: Result | I1: P&L $ | J1: CLV raw | K1: CLV no-vig | L1: Anchor | M1: Process | N1: Notes
A2: 2026-07-29 | B2: Full 5-game slate | C2: No bet - all 10 sides -EV | D2: pass | G2: 0 | H2: validated | I2: 0 | L2: clean | M2: worked | N2: Favorites went 2-3; both most-likely sides blew 6+ run leads; every listed price was -EV vs fair (avg -3.3%). Passing saved money.
A3: 2026-07-29 | B3: BAL @ DET | C3: Tigers ML | D3: order_unfilled | E3: 1.633 | G3: 0 | H3: no fill | I3: 0 | L3: clean | M3: worked | N3: Line closed 1.56-1.59, moving away; discipline held. Tigers lost 9-10 in 12 - a chased fill would have lost.
A4: 2026-07-30 | B4: CHC @ STL | C4: Cubs ML | D4: ticket | E4: 1.991 | F4: 1.99 | G4: 30000 | H4: won | I4: 29700 | J4: -0.005 | K4: -0.0513 | L4: conflict | M4: miss | N4: Cashed on variance: close (CHC +100/STL -120, sharp money on STL) says the edge was not there. Fair missed the no-vig close by 3.7pts on a source-conflict market -> conflict-refusal rule shipped.
A5: 2026-07-30 | B5: PIT @ CIN | C5: Reds ML | D5: order_unfilled | E5: 1.985 | G5: 0 | H5: no fill | I5: 0 | L5: clean | M5: pending | N5: Game pending at grading. Skenes scratched late (bullpen game) - the priced premise changed; listed-pitcher rules would have mattered.
A6: 2026-07-30 | B6: CHC @ STL | C6: Cross-source 'arb' +1.28% | D6: flag | G6: 0 | H6: validated | I6: 0 | L6: conflict | M6: worked | N6: Labeled unverified staleness and not executed; the close proved it was quote drift, not free money.
A7: 2026-07-31 | B7: NYY @ CHC | C7: Market refused (conflict rule) | D7: refusal | G7: 0 | H7: validated | I7: 0 | L7: conflict | M7: worked | N7: Close CHC -140 landed on the sportsbook consensus; Polymarket 52c was the stale outlier (NYY won 2-0 as a +130 dog - vs the close that bet was -7% EV luck). Refusal correct.
A8: 2026-07-31 | B8: PHI @ BAL | C8: Phillies ML | D8: order_open | E8: 2.097 | G8: 0 | H8: no fill | I8: 0 | L8: clean | M8: worked | N8: PHI never traded above 2.06 (target 2.10). Close no-vig PHI 0.467: even at target the bet was -2% vs close - not filling saved money. SportsGrid model lean (PHI 54%) was the wrong side per the close.
A9: 2026-07-31 | B9: PIT @ CIN | C9: Pirates ML | D9: order_open | E9: 1.966 | G9: 0 | H9: no fill | I9: 0 | L9: clean | M9: worked | N9: PIT -120 to -136 all day, never near the 1.966 target. Close no-vig PIT 0.564: a 1.966 fill would have been ~+11% EV vs close - right side, market never paid the price.
A10: 2026-08-01 | B10: PIT @ CIN | C10: Reds ML | D10: order_unfilled | E10: 2.231 | G10: 0 | H10: no fill | I10: 0 | L10: clean | M10: worked | N10: CIN never traded above +106 (2.06) - 17 cents short of the 2.231 bar; the '+120 one source' quote was never corroborated. CIN lost 1-4, so no fill dodged a loss; vs the no-vig close a 2.231 fill would still have been +EV (right side, market never paid).
A11: 2026-08-01 | B11: PIT @ CIN | C11: Pirates ML | D11: order_open | E11: 1.888 | G11: 0 | H11: superseded | I11: 0 | L11: clean | M11: superseded | N11: Superseded by the full-card re-rank (PIT side fell out of the top orders).
A12: 2026-08-01 | B12: NYY @ CHC | C12: Market refused (conflict rule, day 2) | D12: refusal | G12: 0 | H12: validated | I12: 0 | L12: conflict | M12: worked | N12: Refusal correct, with a twist: the close landed NYY road-favorite (-122 to -132; CHC +102/+105) - the OPPOSITE of our 'books CHC 1.62' quote, which no closing book corroborates. That quote was stale/wrong (flagged for provenance). Polymarket NYY 54c was actually the consensus side. CHC won 5-2 anyway - neither side's value story survived. Conflict rule worked for the right reason: garbage inputs were refused, not priced.
A13: 2026-08-01 | B13: WSH @ ATL | C13: Market refused (no anchor >= 0.5) | D13: refusal | G13: 0 | H13: validated | I13: 0 | L13: clean | M13: worked | N13: Braves 8-3. Polymarket-only board stayed unpriced per the 0.45-sharpness demotion; no book close collected for this game.
A14: 2026-08-01 | B14: PHI @ BAL | C14: Orioles ML | D14: order_unfilled | E14: 2.225 | G14: 0 | H14: no fill | I14: 0 | L14: clean | M14: worked | N14: Fill ambiguous: consensus close +119 (2.19) never reached the 2.225 bar, but SportsGrid reported 'BAL +125 at other books' pregame, which would have filled. Graded no-fill on the consensus board we price from. BAL lost 0-5, so neither grading forfeits a win; a phantom fill would have lost. Single-book-anchor caveat from pre-registration stands.
A15: 2026-08-01 | B15: SEA @ POR (MLS) | C15: Timbers ML | D15: order_unfilled | E15: 2.23 | G15: 0 | H15: no fill | I15: 0 | L15: clean | M15: worked | N15: NO BET - user report (the only fill oracle; pages 403 post-hoc): the prediction-market ask had moved above the 45c stand-down line (engine minimum 2.23) by bet time, so per the slip's own fill rule the order did not fire. Paper grade of the 2.273 listed snapshot: Portland won 2-1 and the number beat the bet365 close 2.05/3.80/3.00 by +10.9% raw / +4.5% no-vig - the edge was real at the snapshot, and it decayed before execution. Standing down was correct: at the moved ask the +2.5% EV bar was no longer met.
A16: 2026-08-02 | B16: WSH @ ATL | C16: Braves ML | D16: order_void | E16: 1.866 | G16: 0 | H16: no fill | I16: 0 | L16: clean | M16: miss | N16: VOID - PROCESS MISS (user report): the card shipped hours after this game's 1:35 PM ET first pitch. The container clock read Sunday evening; I overrode it because search snippets showed no Sunday finals - but a lagging search index is not pre-game proof. Order was never actionable; no bet placed, none should be. Original order terms preserved above for the record; outcome deliberately NOT graded (no hindsight grading of a void order).
A17: 2026-08-02 | B17: BOS @ LAD (Sunday Night Baseball) | C17: Dodgers ML | D17: order_void | E17: 1.666 | G17: 0 | H17: no fill | I17: 0 | L17: clean | M17: miss | N17: VOID - cancelled at 7:03 PM ET with first pitch 7:20 PM ET: no time to re-verify the line, and every price on the card is a morning-stale snapshot. An unsupervisable order is not an order.
A18: 2026-08-02 | B18: MIA @ NYM | C18: Marlins ML | D18: order_void | E18: 1.925 | G18: 0 | H18: no fill | I18: 0 | L18: clean | M18: miss | N18: VOID - shipped after the 1:40 PM ET first pitch (same process miss as the headline order). No bet placed, none should be.
A19: 2026-08-02 | B19: PIT @ CIN | C19: Moneyline refused (conflict rule) | D19: refusal | G19: 0 | H19: validated | I19: 0 | L19: conflict | M19: worked | N19: Refusal validated on PROCESS: the book-vs-Polymarket gap (CIN 1.676 vs 55c) never visibly converged before first pitch - the market stayed unpriceable by our rule at every observable snapshot. CIN won 10-2 (Burns 6 IP 9 K) and the close landed -148, but outcome isn't the verdict; the conflict rule is now 4-for-4 on process. Pre-registered under the conflict rule, graded at the close.
A20: 2026-08-03 | B20: STL @ NYY (7:05 PM ET Mon) | C20: Yankees ML | D20: order_unfilled | E20: 1.599 | G20: 0 | H20: no fill | I20: 0 | L20: clean | M20: worked | N20: NOT FILLED - and saved by it. Every dated Monday price moved AWAY from the 1.599 trigger (NYY -186 Sunday -> -195/-210/-217/-235 across books at close); then NYY lost 7-13 (Burleson 3 HR off Schlittler). Our fair (64.1%) sat above a close (~65%) that the result embarrassed - calibration fine, outcome brutal, order discipline kept the stake at zero.
A21: 2026-08-03 | B21: SEA @ NYL (7:00 PM ET Mon) | C21: Liberty ML | D21: order_filled_paper | E21: 1.278 | F21: 1.278 | G21: 0 | H21: won | I21: 0 | J21: -0.0318 | K21: -0.0536 | L21: clean | M21: flagged | N21: FILL CONDITION MET AND CASHED - but read the CLV. Liberty drifted -450 -> -315 close, straight through the 1.278 trigger, and won 95-83. At the conservative fill (1.278) that is NEGATIVE CLV vs the ~1.35 no-vig close: a resting limit order fills precisely when the market moves through it - adverse selection (Walters: the drift was information; the market said the Storm were live-r than our day-old board). Paper grade only, stake 0: this was a backup order, not the headline, and the user bets headline only.
A22: 2026-08-03 | B22: SFG @ TEX (8:05 PM ET Mon) | C22: Rangers ML | D22: order_unfilled | E22: 2.03 | G22: 0 | H22: no fill | I22: 0 | L22: clean | M22: worked | N22: NOT FILLED - TEX never reached plus-money (observed -105 to -125 across books; +103 trigger unreached), then lost 1-5 with five errors behind Webb's 6 shutout IP. Second unfilled loser dodged on the day.
A23: 2026-08-03 | B23: SDP @ AZ (9:40 PM ET Mon) | C23: Board rejected pre-slate (garbled quotes) | D23: flag | G23: 0 | H23: validated | I23: 0 | L23: conflict | M23: worked | N23: Rejection fully validated: the real Monday market was near pick'em with ARI a slight HOME favorite (BetMGM/DK SDP -102 / ARI -118; Yahoo -113) - the garbled 'SD -185/ARI +737' board was wrong on side AND magnitude. ARI won 5-1. Garbage in, nothing out: correct.
A24: 2026-08-06 | B24: ATH @ CIN (start time unverified; typical 12:35 PM ET getaway) | C24: Reds ML | D24: order_unfilled | E24: 1.679 | G24: 0 | H24: no fill | I24: 0 | L24: clean | M24: worked | N24: NOT FILLED: CIN drifted our way (-171 open -> -158 at first pitch) but never reached the -147 (1.679) bar; best documented 1.633. CIN won 6-5, and a 1.679 fill would have carried +2.8% raw CLV vs the close - right side, right price demand, market never paid it. Reverse line movement toward the road dog noted pregame; the bar held anyway.
A25: 2026-08-06 | B25: Dinamo Minsk @ Braga (UECL Q3 leg 1; kickoff ~3:00-3:45 PM ET assumed) | C25: Braga ML (3-way, draw/away lose) | D25: order_unfilled | E25: 1.141 | G25: 0 | H25: no fill | I25: 0 | L25: clean | M25: worked | N25: NOT FILLED: Braga sat 1.10-1.11 everywhere pre-match; the 1.141 re-verified quote never existed. Braga won 1-0. The demotion logic validated exactly: on extreme favorites the only 'fills' available are cross-book noise, and even that noise stayed under 4 cents.
A26: 2026-08-06 | B26: ARI @ CAR, Hall of Fame Game (8:00 PM ET Thu, Canton - neutral site) | C26: Cardinals +1.5 | D26: order_unfilled | E26: 1.88 | G26: 0 | H26: no fill | I26: 0 | L26: clean | M26: worked | N26: NOT FILLED by one cent of juice: ARI +1.5 reached ~-115 game-day vs the -114 bar - and then LOST (CAR won by exactly 3 on the final play). The near-miss dodged a loser; fill discipline is net positive on the card (two would-have-won fills never reached target, the one would-have-lost fill missed by a cent).
A27: 2026-08-06 | B27: ARI @ CAR (HOF Game) | C27: Wong teaser leg suppressed (ARI +1.5 -> +7.5) | D27: flag | G27: 0 | H27: validated | I27: 0 | L27: clean | M27: worked | N27: Suppression validated on process with an ironic outcome: the suppressed leg (ARI +1.5 -> +7.5) would have back-doored a win (lost by 3), but the game produced 63 points against a 34.5 total - preseason margins have NO key-number structure, which is precisely why the leg had no business existing. Note-only; engine gating change still deferred (Walters rule).
A28: 2026-08-10 | B28: NYM @ ATL (7:15 PM ET Mon) | C28: Braves ML | D28: order_filled | E28: 1.684 | F28: 1.684 | G28: 0 | H28: lost | I28: 0 | J28: -0.0152 | K28: -0.0305 | L28: clean | M28: flagged | N28: FILLED AND LOST - first filled headline order. The trigger (1.684/-147) verifiably printed at multiple books (-138 Covers, -140 FanDuel, -143 Caesars) before first pitch; ATL lost 8-5. Graded at the 1.684 floor: raw CLV -1.5%, no-vig -3.1% - NEGATIVE, the second straight drift-fill with negative CLV (Liberty Aug-3 was the first). The market drifted toward the Mets all day and the drift was information; re-priced at the drifted number, our own blend no longer cleared the bar. DRIFT-CANCEL RULE shipped to CLAUDE.md off this graded pair. User stake unconfirmed - tracker computes the loss at your unit stake; if you passed on it, tell me and I regrade to no-bet (Timbers precedent).
A29: 2026-08-10 | B29: Shnaider vs Swiatek, WTA Toronto QF (7:00 PM ET Mon) | C29: Swiatek ML | D29: order_unfilled | E29: 1.403 | G29: 0 | H29: no fill | I29: 0 | L29: clean | M29: worked | N29: NOT FILLED: no book ever printed 1.403+ (-285/-300 everywhere). Swiatek won 6-2 6-1 - a missed winner, which is the cost side of the same discipline that has dodged three losers. The bar cuts both ways; that is the design.
A30: 2026-08-10 | B30: COL @ AZ (Chase Field, evening - exact time TBC) | C30: Diamondbacks ML | D30: order_unfilled | E30: 1.624 | G30: 0 | H30: no fill | I30: 0 | L30: clean | M30: worked | N30: NOT FILLED: line moved AWAY from the order all day (-179 -> -190s; the -164 outlier board never reached -160). Game in progress at grading - outcome irrelevant to an unfilled order.
A31: 2026-08-10 | B31: KC @ LAD (10:10 PM ET Mon - Skubal home debut) | C31: Moneyline refused (conflict rule) | D31: refusal | G31: 0 | H31: validated | I31: 0 | L31: conflict | M31: worked | N31: VALIDATED, with the sharpest twist yet: the definitive Monday close was LAD -325/-330 (FanDuel + 'other oddsmakers' + Polymarket 74c all agree near 76%) - the -160 board we saw was itself a stale/erroneous print. The conflict was real, and this time the BOOK leg was the garbage and the prediction market was near truth (mirror of the Aug-1 stale 'CHC 1.62'). The rule doesn't care which source lies - it refuses the disagreement. LAD needed a 7th-inning rally to win 6-5. 7-for-7 on refusals/flags.
A32: 2026-08-11 | B32: CLE @ DET (6:40 PM ET Tue, Comerica) | C32: Tigers ML | D32: order_unfilled | E32: 2.164 | G32: 0 | H32: no fill | I32: 0 | L32: clean | M32: worked | N32: NOT FILLED - the market ran the other way, hard: DET +113 Monday night -> -120/-121 favorite at first pitch. No +116 ever printed. DET won 6-4, so another would-have-won missed - but the swing's SIZE is the lesson: an overnight board can embed a different starting pitcher than game-day reality (Drew Anderson started). Listed-pitcher rule: every future order names its assumed starters, and a change voids the premise (Skenes-scratch lesson, Jul 30, finally codified).
A33: 2026-08-11 | B33: TB @ ATH (9:40 PM ET Tue) | C33: Rays ML | D33: order_unfilled | E33: 1.72 | G33: 0 | H33: no fill | I33: 0 | L33: clean | M33: worked | N33: NOT FILLED - TB shortened -146 -> -180 and won 12-4. Fourth straight unfilled order whose side won. Tempting to call the bar too high; the ledger says otherwise - the only two orders that DID fill both carried negative CLV and went 1-1. Unfilled winners are the visible cost of refusing bad prices; filled losers are the invisible cost of chasing. No parameter change (Walters rule).
A34: 2026-08-11 | B34: KC @ LAD (10:10 PM ET Tue) | C34: Moneyline refused (conflict rule, day 2) | D34: refusal | G34: 0 | H34: validated | I34: 0 | L34: conflict | M34: worked | N34: Book LAD -285 vs Polymarket 72c: nearly agreeing today, but cross-source best prices still net -0.99% hold - the rule is binary and fires the same on small conflicts as wide ones (that binariness is the Cubs-3.7pt lesson). 6th application. Monday's refusal grades at its close next cycle alongside this one. || SETTLED: close LAD -275 (~70-71% no-vig) vs Polymarket 72c - the sources converged AT the close, meaning no exploitable edge ever existed. LAD won 5-4. Refusals now 8-for-8.
A35: 2026-08-12 | B35: NYM @ ATL (7:15 PM ET Wed; PITCHERS: Thornton vs Mahle) | C35: Braves ML | D35: order_unfilled | E35: 1.666 | G35: 0 | H35: no fill | I35: 0 | L35: clean | M35: worked | N35: NOT FILLED - the board moved the wrong way all day (-156 -> -158/-175 close); -150 never printed. ATL won 6-3: the FIFTH straight unfilled order whose side won. Pattern reading: our fairs are directionally right and the market agrees too fast to pay our price - which is what near-parity Brier with the close predicts. The bar stays (Walters rule); the edge has to come from being earlier, not looser.
A36: 2026-08-12 | B36: ATP Montreal SF: Jodar vs Nakashima (6:00 PM ET Wed) | C36: Nakashima ML | D36: order_filled_paper | E36: 2.969 | F36: 2.969 | G36: 0 | H36: won | I36: 0 | J36: 0.0099 | K36: -0.0173 | L36: clean | M36: worked | N36: FILL CONDITION MET VIA CROSS-BOOK SHOPPING - AND WON. +200 (>= the +197 trigger) was genuinely available at a book pre-match while Dimers' board showed +188; Nakashima won 7-6(3) 6-4. At the 2.969 floor vs the 2.94 close: raw CLV +1.0%, no-vig -1.7% - the first fill in this ledger with POSITIVE RAW CLV and the best fill-CLV recorded (prior fills: -5.4% and -3.1% no-vig), precisely because it came from price dispersion across books (allowed) rather than line drift (forbidden). The drift-vs-shopping distinction now has favorable evidence on the shopping side. Paper grade, stake 0 - backup order, user bets headline only.
A37: 2026-08-12 | B37: SEA @ NYY (7:05 PM ET Wed; PITCHERS: Miller vs Warren) | C37: Yankees ML | D37: order_unfilled | E37: 1.893 | G37: 0 | H37: no fill | I37: 0 | L37: clean | M37: worked | N37: NOT FILLED - opened -119 and firmed to -131; the -112 trigger never printed. NYY won 10-5 anyway (sixth unfilled winner if you count this one alongside the ATL streak).
A38: 2026-08-13 | B38: MIL @ LAD (10:10 PM ET Thu; PITCHERS: Drohan vs Sasaki) | C38: Brewers ML | D38: order_unfilled | E38: 2.353 | G38: 0 | H38: no fill | I38: 0 | L38: clean | M38: worked | N38: NOT FILLED - EdgeBets' 8-book closing recap tops MIL out at +129 (range +115/+129, consensus +123/+125); the +136 trigger never printed anywhere. Both listed pitchers started (Shane Drohan vs Sasaki) so the premise held; the price just never came. MIL won 5-4 on a 3-run 9th - the SEVENTH unfilled order whose side won. The bar stays (Walters rule): the two orders that ever DID fill via drift carried the ledger's worst CLV.
A39: 2026-08-13 | B39: PHI @ MIN, Field of Dreams (7:30 PM ET; Nola vs Bradley; RAIN RISK) | C39: Over 8.5 | D39: order_unfilled | E39: 1.937 | G39: 0 | H39: no fill | I39: 0 | L39: clean | M39: worked | N39: NOT FILLED - Over sat -118/-120 all day and never reached the -107 trigger. Game went UNDER (8 runs): the FIRST unfilled order whose side LOST, i.e. the bar's first visible counterfactual save (~$40 at quarter-Kelly). The unfilled-order ledger is now 7 winners, 1 loser - and the loser is the one the bar refused to pay for. First graded third-party total model (SportsLine 60.2% over): WRONG. Rain clause never triggered - played as scheduled.
A40: 2026-08-13 | B40: PHI @ MIN, Field of Dreams (same game) | C40: Phillies ML | D40: order_unfilled | E40: 2.063 | G40: 0 | H40: no fill | I40: 0 | L40: clean | M40: worked | N40: NOT FILLED - PHI ranged -102/-104 all day and closed ~-103 (SBR); the +106 trigger needed plus-money that never printed. PHI won 7-1 (Schwarber 2 HR) - the EIGHTH unfilled order graded, 7 of whose sides won.
...

Sheet FairLines
A1: Date | B1: Event | C1: Our fair (home) | D1: Close no-vig (home) | E1: Error (pts) | F1: Home won (1/0) | G1: Brier ours | H1: Brier close | I1: Source flag
A2: 2026-07-29 | B2: mlb-2026-07-29-bal-det | C2: 0.6184 | D2: 0.6225 | E2: =ABS(C2-D2)*100 | F2: 0 | G2: =(C2-F2)^2 | H2: =(D2-F2)^2 | I2: clean
A3: 2026-07-29 | B3: mlb-2026-07-29-atl-nym-g1 | C3: 0.4953 | D3: 0.4907 | E3: =ABS(C3-D3)*100 | F3: 1 | G3: =(C3-F3)^2 | H3: =(D3-F3)^2 | I3: clean
A4: 2026-07-29 | B4: mlb-2026-07-29-col-sd | C4: 0.5644 | D4: 0.5617 | E4: =ABS(C4-D4)*100 | F4: 1 | G4: =(C4-F4)^2 | H4: =(D4-F4)^2 | I4: clean
A5: 2026-07-29 | B5: mlb-2026-07-29-tor-wsh | C5: 0.4653 | D5: 0.4678 | E5: =ABS(C5-D5)*100 | F5: 0 | G5: =(C5-F5)^2 | H5: =(D5-F5)^2 | I5: clean
A6: 2026-07-29 | B6: mlb-2026-07-29-phi-mia | C6: 0.4108 | D6: 0.3865 | E6: =ABS(C6-D6)*100 | F6: 1 | G6: =(C6-F6)^2 | H6: =(D6-F6)^2 | I6: clean
A7: 2026-07-30 | B7: mlb-2026-07-30-tex-tb | C7: 0.6203 | D7: 0.5713 | E7: =ABS(C7-D7)*100 | F7: 1 | G7: =(C7-F7)^2 | H7: =(D7-F7)^2 | I7: low-conf close
A8: 2026-07-30 | B8: mlb-2026-07-30-chc-stl | C8: 0.4852 | D8: 0.5233 | E8: =ABS(C8-D8)*100 | F8: 0 | G8: =(C8-F8)^2 | H8: =(D8-F8)^2 | I8: conflict
A9: 2026-07-30 | B9: mlb-2026-07-30-mia-nym | C9: 0.5522 | D9: 0.5454 | E9: =ABS(C9-D9)*100 | F9: 1 | G9: =(C9-F9)^2 | H9: =(D9-F9)^2 | I9: clean
A10: 2026-07-30 | B10: mlb-2026-07-30-wsh-atl | C10: 0.5255 | D10: 0.5665 | E10: =ABS(C10-D10)*100 | F10: 1 | G10: =(C10-F10)^2 | H10: =(D10-F10)^2 | I10: stale quote
A11: 2026-07-30 | B11: mlb-2026-07-30-bos-ath | C11: 0.4117 | D11: 0.3733 | E11: =ABS(C11-D11)*100 | F11: 0 | G11: =(C11-F11)^2 | H11: =(D11-F11)^2 | I11: low-conf close
A12: 2026-07-30 | B12: mlb-2026-07-30-nyy-cws | C12: 0.4317 | D12: 0.5115 | E12: =ABS(C12-D12)*100 | F12: 1 | G12: =(C12-F12)^2 | H12: =(D12-F12)^2 | I12: date trap
A13: 2026-07-30 | B13: mlb-2026-07-30-sea-lad | C13: 0.5883 | D13: 0.5934 | E13: =ABS(C13-D13)*100 | F13: 1 | G13: =(C13-F13)^2 | H13: =(D13-F13)^2 | I13: clean
... A228: 2026-09-04 | B228: wta-2026-09-04-svi-kal | C228: 0.2874 | D228: 0.2816 | E228: =ABS(C228-D228)*100 | F228: 1 | G228: =(C228-F228)^2 | H228: =(D228-F228)^2 | I228: clean

Sheet Dashboard
A1: SharpOds Tracker — Dashboard
A2: Every value below is a formula over Bets/FairLines: add or settle rows there and this sheet recomputes.
A5: Tickets settled | B5: =COUNTIFS(Bets!D:D,"ticket",Bets!H:H,"<>pending")
A6: Ticket wins | B6: =COUNTIFS(Bets!D:D,"ticket",Bets!H:H,"won")
A7: Win rate | B7: =IFERROR(B6/B5,0)
A8: Total staked | B8: =SUMIFS(Bets!G:G,Bets!D:D,"ticket",Bets!H:H,"<>pending")
A9: Net P&L | B9: =SUM(Bets!I:I)
A10: ROI on stakes | B10: =IFERROR(B9/B8,0)
A11: Mean CLV (no-vig), tickets | B11: =IFERROR(AVERAGEIFS(Bets!K:K,Bets!D:D,"ticket"),0)
A12: Limit orders unfilled | B12: =COUNTIF(Bets!D:D,"order_unfilled")
A13: Open orders / pending | B13: =COUNTIF(Bets!H:H,"pending")
A14: Decisions settled | B14: =COUNTIF(Bets!M:M,"worked")+COUNTIF(Bets!M:M,"miss")
A15: Process validated (worked) | B15: =COUNTIF(Bets!M:M,"worked")
A16: Process misses | B16: =COUNTIF(Bets!M:M,"miss")
A17: Fair lines graded | B17: =COUNT(FairLines!E:E)
A18: Mean |fair − close| (pts) | B18: =IFERROR(AVERAGE(FairLines!E:E),0)
A19: Max |fair − close| (pts) | B19: =IFERROR(MAX(FairLines!E:E),0)
A20: Clean-source mean error (pts) | B20: =IFERROR(AVERAGEIFS(FairLines!E:E,FairLines!I:I,"clean"),0)
A21: Flagged-source mean error (pts) | B21: =IFERROR(AVERAGEIFS(FairLines!E:E,FairLines!I:I,"<>clean"),0)
A22: Brier — SharpOds fair | B22: =IFERROR(AVERAGE(FairLines!G:G),0)
A23: Brier — closing line | B23: =IFERROR(AVERAGE(FairLines!H:H),0)
A24: Brier — coin flip (reference) | B24: =0.25
A27: What worked / what didn't (from the decision log)
A28: [WORKED] Full 5-game slate: Favorites went 2-3; both most-likely sides blew 6+ run leads; every listed price was -EV vs fair (avg -3.3%). Passing saved money.
A29: [WORKED] BAL @ DET: Line closed 1.56-1.59, moving away; discipline held. Tigers lost 9-10 in 12 - a chased fill would have lost.
A30: [WORKED] CHC @ STL: Labeled unverified staleness and not executed; the close proved it was quote drift, not free money.
A31: [WORKED] NYY @ CHC: Close CHC -140 landed on the sportsbook consensus; Polymarket 52c was the stale outlier (NYY won 2-0 as a +130 dog - vs the close that bet was -7% EV luck). Refusal correct.
A32: [WORKED] PHI @ BAL: PHI never traded above 2.06 (target 2.10). Close no-vig PHI 0.467: even at target the bet was -2% vs close - not filling saved money. SportsGrid model lean (PHI 54%) was the wrong side per the close.
A33: [WORKED] PIT @ CIN: PIT -120 to -136 all day, never near the 1.966 target. Close no-vig PIT 0.564: a 1.966 fill would have been ~+11% EV vs close - right side, market never paid the price.
A34: [WORKED] PIT @ CIN: CIN never traded above +106 (2.06) - 17 cents short of the 2.231 bar; the '+120 one source' quote was never corroborated. CIN lost 1-4, so no fill dodged a loss; vs the no-vig close a 2.231 fill would still have been +EV (right side, market never paid).
A35: [WORKED] NYY @ CHC: Refusal correct, with a twist: the close landed NYY road-favorite (-122 to -132; CHC +102/+105) - the OPPOSITE of our 'books CHC 1.62' quote, which no closing book corroborates. That quote was stale/wrong (flagged for provenance). Polymarket NYY 54c was actually the consensus side. CHC won 5-2 anyway - neither side's value story survived. Conflict rule worked for the right reason: garbage inputs were refused, not priced.
A36: [WORKED] WSH @ ATL: Braves 8-3. Polymarket-only board stayed unpriced per the 0.45-sharpness demotion; no book close collected for this game.
A37: [WORKED] PHI @ BAL: Fill ambiguous: consensus close +119 (2.19) never reached the 2.225 bar, but SportsGrid reported 'BAL +125 at other books' pregame, which would have filled. Graded no-fill on the consensus board we price from. BAL lost 0-5, so neither grading forfeits a win; a phantom fill would have lost. Single-book-anchor caveat from pre-registration stands.
A38: [WORKED] SEA @ POR (MLS): NO BET - user report (the only fill oracle; pages 403 post-hoc): the prediction-market ask had moved above the 45c stand-down line (engine minimum 2.23) by bet time, so per the slip's own fill rule the order did not fire. Paper grade of the 2.273 listed snapshot: Portland won 2-1 and the number beat the bet365 close 2.05/3.80/3.00 by +10.9% raw / +4.5% no-vig - the edge was real at the snapshot, and it decayed before execution. Standing down was correct: at the moved ask the +2.5% EV bar was no longer met.
... A98: Source: data/track_record.json (SharpOds ledger); regenerated by `sharpods-tracker`. Assumption: closing lines are best-available day-of published numbers, not exchange-verified closing ticks.
